Workbook

Sheet Sheet3
B3: Count of ID PICA
B4: 2465 | C4: =GETPIVOTDATA("ID PICA",$B$3) -> 2465 | I4: Awarded | J4: =COUNTIF('Table 1'!G:G,"Awarded") -> 20 | L4: Row Labels | M4: Count of Category | N4: Category | O4: Percentage
F5: Row Labels | G5: Count of EMJM Scholarship | I5: Awaiting | J5: =COUNTIF('Table 1'!G:G,"waiting list") -> 110 | L5: Double Yes | M5: 70 | N5: Double Yes | O5: =GETPIVOTDATA("Category",$L$4,"Category","Double Yes")/GETPIVOTDATA("Category",$L$4) -> 0.028397566
B6: Row Labels | C6: Count of ID PICA | F6: Bangladesh | G6: 8 | I6: N/A | J6: =COUNTIF('Table 1'!G:G,"N/A") -> 189 | L6: Single Yes | M6: 119 | N6: Single Yes | O6: =GETPIVOTDATA("Category",$L$4,"Category","Single Yes")/GETPIVOTDATA("Category",$L$4) -> 0.048275862
B7: No | C7: 2335 | D7: =GETPIVOTDATA("ID PICA",$B$6,"Selected IM","No") -> 2335 | F7: Cameroon | G7: 29 | I7: No Decision | J7: =COUNTIF(Table1[EMJM Scholarship],"") -> 2146 | L7: Triple No | M7: 2146 | N7: Triple No | O7: =GETPIVOTDATA("Category",$L$4,"Category","Triple No")/GETPIVOTDATA("Category",$L$4) -> 0.87058824
B8: Yes | C8: 130 | D8: =GETPIVOTDATA("ID PICA",$B$6,"Selected IM","Yes") -> 130 | F8: India | G8: 13 | L8: Triple Yes | M8: 130 | N8: Triple Yes | O8: =GETPIVOTDATA("Category",$L$4,"Category","Triple Yes")/GETPIVOTDATA("Category",$L$4) -> 0.052738337
B9: Grand Total | C9: 2465 | F9: Iran | G9: 10 | I9: Intermath | J9: =COUNTIF('Table 1'!C:C,"Yes") -> 130 | L9: Grand Total | M9: 2465
F10: Kazakhstan | G10: 9 | I10: MM | J10: =COUNTIF('Table 1'!D:D,"Yes") -> 200
F11: Nigeria | G11: 30 | I11: RM | J11: =COUNTIF('Table 1'!E:E,"Yes") -> 319
F12: Pakistan | G12: 35
F13: Rwanda | G13: 10
F14: Spain | G14: 9
F15: Uganda | G15: 16 | I15: {=_xlfn.UNIQUE('Table 1'!B:B)} -> Nationality
F16: Vietnam | G16: 8 | I16: Italy | J16: =COUNTIF('Table 1'!B:B,Sheet3!I16) -> 4
F17: Grand Total | G17: 177 | I17: Croatia | J17: =COUNTIF('Table 1'!B:B,Sheet3!I17) -> 1
I18: Spain | J18: =COUNTIF('Table 1'!B:B,Sheet3!I18) -> 9
I19: Australia | J19: =COUNTIF('Table 1'!B:B,Sheet3!I19) -> 2
I20: Vietnam | J20: =COUNTIF('Table 1'!B:B,Sheet3!I20) -> 8
I21: Koreasouth | J21: =COUNTIF('Table 1'!B:B,Sheet3!I21) -> 1
F22: Row Labels | G22: Count of EMJM Scholarship | I22: United States Of America | J22: =COUNTIF('Table 1'!B:B,Sheet3!I22) -> 7
I23: Russia | J23: =COUNTIF('Table 1'!B:B,Sheet3!I23) -> 2
F24: Belgium | G24: 1 | I24: Germany | J24: =COUNTIF('Table 1'!B:B,Sheet3!I24) -> 5
F25: Cambodia | G25: 1 | I25: Kazakhstan | J25: =COUNTIF('Table 1'!B:B,Sheet3!I25) -> 9
F26: Chile | G26: 1 | I26: India | J26: =COUNTIF('Table 1'!B:B,Sheet3!I26) -> 13
F27: Congo | G27: 1 | I27: United Kingdom | J27: =COUNTIF('Table 1'!B:B,Sheet3!I27) -> 1
F28: Croatia | G28: 1 | I28: Ireland | J28: =COUNTIF('Table 1'!B:B,Sheet3!I28) -> 3
F29: Greece | G29: 1 | I29: China | J29: =COUNTIF('Table 1'!B:B,Sheet3!I29) -> 7
F30: Honduras | G30: 1 | I30: Southafrica | J30: =COUNTIF('Table 1'!B:B,Sheet3!I30) -> 2
F31: Koreasouth | G31: 1 | I31: Colombia | J31: =COUNTIF('Table 1'!B:B,Sheet3!I31) -> 7
F32: Kosovo | G32: 1 | I32: Ukraine | J32: =COUNTIF('Table 1'!B:B,Sheet3!I32) -> 4
F33: Latvia | G33: 1 | I33: Pakistan | J33: =COUNTIF('Table 1'!B:B,Sheet3!I33) -> 35
F34: Lithuania | G34: 1 | I34: Argentina | J34: =COUNTIF('Table 1'!B:B,Sheet3!I34) -> 2
F35: Macedonia | G35: 1 | I35: Iran | J35: =COUNTIF('Table 1'!B:B,Sheet3!I35) -> 10
... F41: Tanzania | G41: 1 | I41: Turkey | J41: =COUNTIF('Table 1'!B:B,Sheet3!I41) -> 4
F42: Thailand | G42: 1 | I42: Ethiopia | J42: =COUNTIF('Table 1'!B:B,Sheet3!I42) -> 6 | K42: =MAX(J16:J79) -> 35
F43: The Gambia | G43: 1 | I43: Nigeria | J43: =COUNTIF('Table 1'!B:B,Sheet3!I43) -> 30 | K43: =_xlfn.XLOOKUP(K42,J16:J81,I16:I81) -> Pakistan
F44: Tunisia | G44: 1 | I44: Bangladesh | J44: =COUNTIF('Table 1'!B:B,Sheet3!I44) -> 8
F45: United Kingdom | G45: 1 | I45: Ecuador | J45: =COUNTIF('Table 1'!B:B,Sheet3!I45) -> 6
F46: Zimbabwe | G46: 1 | I46: France | J46: =COUNTIF('Table 1'!B:B,Sheet3!I46) -> 2
F47: Grand Total | G47: 23 | I47: Egypt | J47: =COUNTIF('Table 1'!B:B,Sheet3!I47) -> 7
...

Sheet Table 1
A1: ID PICA | B1: Nationality | C1: Selected IM | D1: Selected MM | E1: Selected RM | F1: SCORE | G1: EMJM Scholarship | H1: Ranking | I1: Category | J1: Nigeria
A2: 2503059 | B2: Italy | C2: Yes | D2: Yes | E2: Yes | F2: 99.55 | G2: Awarded | H2: 1 | I2: =IF(AND(Table1[[#This Row],[Selected IM]]="Yes",Table1[[#This Row],[Selected MM]]="Yes",Table1[[#This Row],[Selected RM]]="Yes"),"Triple Yes",IF(OR((AND(Table1[[#This Row],[Selected IM]]="Yes",Table1[[#This Row],[Selected MM]]="No",Table1[[#This Row],[Selected RM]]="Yes")),(AND(Table1[[#This Row],[Selected IM]]="No",Table1[[#This Row],[Selected MM]]="Yes",Table1[[#This Row],[Selected RM]]="Yes"))),"Double Yes", IF(AND(Table1[[#This Row],[Selected IM]]="No",Table1[[#This Row],[Selected MM]]="No",Table1[[#This Row],[Selected RM]]="Yes"), "Single Yes", "Triple No"))) -> Triple Yes | J2: =IF(Table1[[#This Row],[Nationality]]="Nigeria",Table1[[#This Row],[EMJM Scholarship]],"Not Applicable") -> Not Applicable
A3: 2522846 | B3: Italy | C3: Yes | D3: Yes | E3: Yes | F3: 99.16 | G3: Awarded | H3: 2 | I3: =IF(AND(Table1[[#This Row],[Selected IM]]="Yes",Table1[[#This Row],[Selected MM]]="Yes",Table1[[#This Row],[Selected RM]]="Yes"),"Triple Yes",IF(OR((AND(Table1[[#This Row],[Selected IM]]="Yes",Table1[[#This Row],[Selected MM]]="No",Table1[[#This Row],[Selected RM]]="Yes")),(AND(Table1[[#This Row],[Selected IM]]="No",Table1[[#This Row],[Selected MM]]="Yes",Table1[[#This Row],[Selected RM]]="Yes"))),"Double Yes", IF(AND(Table1[[#This Row],[Selected IM]]="No",Table1[[#This Row],[Selected MM]]="No",Table1[[#This Row],[Selected RM]]="Yes"), "Single Yes", "Triple No"))) -> Triple Yes | J3: =IF(Table1[[#This Row],[Nationality]]="Nigeria",Table1[[#This Row],[EMJM Scholarship]],"Not Applicable") -> Not Applicable
A4: 2457953 | B4: Croatia | C4: Yes | D4: Yes | E4: Yes | F4: 98.74 | G4: Awarded | H4: 3 | I4: =IF(AND(Table1[[#This Row],[Selected IM]]="Yes",Table1[[#This Row],[Selected MM]]="Yes",Table1[[#This Row],[Selected RM]]="Yes"),"Triple Yes",IF(OR((AND(Table1[[#This Row],[Selected IM]]="Yes",Table1[[#This Row],[Selected MM]]="No",Table1[[#This Row],[Selected RM]]="Yes")),(AND(Table1[[#This Row],[Selected IM]]="No",Table1[[#This Row],[Selected MM]]="Yes",Table1[[#This Row],[Selected RM]]="Yes"))),"Double Yes", IF(AND(Table1[[#This Row],[Selected IM]]="No",Table1[[#This Row],[Selected MM]]="No",Table1[[#This Row],[Selected RM]]="Yes"), "Single Yes", "Triple No"))) -> Triple Yes | J4: =IF(Table1[[#This Row],[Nationality]]="Nigeria",Table1[[#This Row],[EMJM Scholarship]],"Not Applicable") -> Not Applicable
A5: 2514655 | B5: Spain | C5: Yes | D5: Yes | E5: Yes | F5: 96.69 | G5: Awarded | H5: 4 | I5: =IF(AND(Table1[[#This Row],[Selected IM]]="Yes",Table1[[#This Row],[Selected MM]]="Yes",Table1[[#This Row],[Selected RM]]="Yes"),"Triple Yes",IF(OR((AND(Table1[[#This Row],[Selected IM]]="Yes",Table1[[#This Row],[Selected MM]]="No",Table1[[#This Row],[Selected RM]]="Yes")),(AND(Table1[[#This Row],[Selected IM]]="No",Table1[[#This Row],[Selected MM]]="Yes",Table1[[#This Row],[Selected RM]]="Yes"))),"Double Yes", IF(AND(Table1[[#This Row],[Selected IM]]="No",Table1[[#This Row],[Selected MM]]="No",Table1[[#This Row],[Selected RM]]="Yes"), "Single Yes", "Triple No"))) -> Triple Yes | J5: =IF(Table1[[#This Row],[Nationality]]="Nigeria",Table1[[#This Row],[EMJM Scholarship]],"Not Applicable") -> Not Applicable
A6: 2521687 | B6: Australia | C6: Yes | D6: Yes | E6: Yes | F6: 96 | G6: Awarded | H6: 5 | I6: =IF(AND(Table1[[#This Row],[Selected IM]]="Yes",Table1[[#This Row],[Selected MM]]="Yes",Table1[[#This Row],[Selected RM]]="Yes"),"Triple Yes",IF(OR((AND(Table1[[#This Row],[Selected IM]]="Yes",Table1[[#This Row],[Selected MM]]="No",Table1[[#This Row],[Selected RM]]="Yes")),(AND(Table1[[#This Row],[Selected IM]]="No",Table1[[#This Row],[Selected MM]]="Yes",Table1[[#This Row],[Selected RM]]="Yes"))),"Double Yes", IF(AND(Table1[[#This Row],[Selected IM]]="No",Table1[[#This Row],[Selected MM]]="No",Table1[[#This Row],[Selected RM]]="Yes"), "Single Yes", "Triple No"))) -> Triple Yes | J6: =IF(Table1[[#This Row],[Nationality]]="Nigeria",Table1[[#This Row],[EMJM Scholarship]],"Not Applicable") -> Not Applicable
A7: 2486151 | B7: Vietnam | C7: Yes | D7: Yes | E7: Yes | F7: 95.83 | G7: Awarded | H7: 6 | I7: =IF(AND(Table1[[#This Row],[Selected IM]]="Yes",Table1[[#This Row],[Selected MM]]="Yes",Table1[[#This Row],[Selected RM]]="Yes"),"Triple Yes",IF(OR((AND(Table1[[#This Row],[Selected IM]]="Yes",Table1[[#This Row],[Selected MM]]="No",Table1[[#This Row],[Selected RM]]="Yes")),(AND(Table1[[#This Row],[Selected IM]]="No",Table1[[#This Row],[Selected MM]]="Yes",Table1[[#This Row],[Selected RM]]="Yes"))),"Double Yes", IF(AND(Table1[[#This Row],[Selected IM]]="No",Table1[[#This Row],[Selected MM]]="No",Table1[[#This Row],[Selected RM]]="Yes"), "Single Yes", "Triple No"))) -> Triple Yes | J7: =IF(Table1[[#This Row],[Nationality]]="Nigeria",Table1[[#This Row],[EMJM Scholarship]],"Not Applicable") -> Not Applicable
A8: 2414635 | B8: Koreasouth | C8: Yes | D8: Yes | E8: Yes | F8: 95.62 | G8: Awarded | H8: 7 | I8: =IF(AND(Table1[[#This Row],[Selected IM]]="Yes",Table1[[#This Row],[Selected MM]]="Yes",Table1[[#This Row],[Selected RM]]="Yes"),"Triple Yes",IF(OR((AND(Table1[[#This Row],[Selected IM]]="Yes",Table1[[#This Row],[Selected MM]]="No",Table1[[#This Row],[Selected RM]]="Yes")),(AND(Table1[[#This Row],[Selected IM]]="No",Table1[[#This Row],[Selected MM]]="Yes",Table1[[#This Row],[Selected RM]]="Yes"))),"Double Yes", IF(AND(Table1[[#This Row],[Selected IM]]="No",Table1[[#This Row],[Selected MM]]="No",Table1[[#This Row],[Selected RM]]="Yes"), "Single Yes", "Triple No"))) -> Triple Yes | J8: =IF(Table1[[#This Row],[Nationality]]="Nigeria",Table1[[#This Row],[EMJM Scholarship]],"Not Applicable") -> Not Applicable
A9: 2478579 | B9: United States Of America | C9: Yes | D9: Yes | E9: Yes | F9: 94.59 | G9: Awarded | H9: 8 | I9: =IF(AND(Table1[[#This Row],[Selected IM]]="Yes",Table1[[#This Row],[Selected MM]]="Yes",Table1[[#This Row],[Selected RM]]="Yes"),"Triple Yes",IF(OR((AND(Table1[[#This Row],[Selected IM]]="Yes",Table1[[#This Row],[Selected MM]]="No",Table1[[#This Row],[Selected RM]]="Yes")),(AND(Table1[[#This Row],[Selected IM]]="No",Table1[[#This Row],[Selected MM]]="Yes",Table1[[#This Row],[Selected RM]]="Yes"))),"Double Yes", IF(AND(Table1[[#This Row],[Selected IM]]="No",Table1[[#This Row],[Selected MM]]="No",Table1[[#This Row],[Selected RM]]="Yes"), "Single Yes", "Triple No"))) -> Triple Yes | J9: =IF(Table1[[#This Row],[Nationality]]="Nigeria",Table1[[#This Row],[EMJM Scholarship]],"Not Applicable") -> Not Applicable
A10: 2522956 | B10: Russia | C10: Yes | D10: Yes | E10: Yes | F10: 94.32 | G10: Awarded | H10: 9 | I10: =IF(AND(Table1[[#This Row],[Selected IM]]="Yes",Table1[[#This Row],[Selected MM]]="Yes",Table1[[#This Row],[Selected RM]]="Yes"),"Triple Yes",IF(OR((AND(Table1[[#This Row],[Selected IM]]="Yes",Table1[[#This Row],[Selected MM]]="No",Table1[[#This Row],[Selected RM]]="Yes")),(AND(Table1[[#This Row],[Selected IM]]="No",Table1[[#This Row],[Selected MM]]="Yes",Table1[[#This Row],[Selected RM]]="Yes"))),"Double Yes", IF(AND(Table1[[#This Row],[Selected IM]]="No",Table1[[#This Row],[Selected MM]]="No",Table1[[#This Row],[Selected RM]]="Yes"), "Single Yes", "Triple No"))) -> Triple Yes | J10: =IF(Table1[[#This Row],[Nationality]]="Nigeria",Table1[[#This Row],[EMJM Scholarship]],"Not Applicable") -> Not Applicable
A11: 2490947 | B11: Spain | C11: Yes | D11: Yes | E11: Yes | F11: 94.27 | G11: Awarded | H11: 10 | I11: =IF(AND(Table1[[#This Row],[Selected IM]]="Yes",Table1[[#This Row],[Selected MM]]="Yes",Table1[[#This Row],[Selected RM]]="Yes"),"Triple Yes",IF(OR((AND(Table1[[#This Row],[Selected IM]]="Yes",Table1[[#This Row],[Selected MM]]="No",Table1[[#This Row],[Selected RM]]="Yes")),(AND(Table1[[#This Row],[Selected IM]]="No",Table1[[#This Row],[Selected MM]]="Yes",Table1[[#This Row],[Selected RM]]="Yes"))),"Double Yes", IF(AND(Table1[[#This Row],[Selected IM]]="No",Table1[[#This Row],[Selected MM]]="No",Table1[[#This Row],[Selected RM]]="Yes"), "Single Yes", "Triple No"))) -> Triple Yes | J11: =IF(Table1[[#This Row],[Nationality]]="Nigeria",Table1[[#This Row],[EMJM Scholarship]],"Not Applicable") -> Not Applicable
A12: 2490010 | B12: Germany | C12: Yes | D12: Yes | E12: Yes | F12: 93.81 | G12: Awarded | H12: 11 | I12: =IF(AND(Table1[[#This Row],[Selected IM]]="Yes",Table1[[#This Row],[Selected MM]]="Yes",Table1[[#This Row],[Selected RM]]="Yes"),"Triple Yes",IF(OR((AND(Table1[[#This Row],[Selected IM]]="Yes",Table1[[#This Row],[Selected MM]]="No",Table1[[#This Row],[Selected RM]]="Yes")),(AND(Table1[[#This Row],[Selected IM]]="No",Table1[[#This Row],[Selected MM]]="Yes",Table1[[#This Row],[Selected RM]]="Yes"))),"Double Yes", IF(AND(Table1[[#This Row],[Selected IM]]="No",Table1[[#This Row],[Selected MM]]="No",Table1[[#This Row],[Selected RM]]="Yes"), "Single Yes", "Triple No"))) -> Triple Yes | J12: =IF(Table1[[#This Row],[Nationality]]="Nigeria",Table1[[#This Row],[EMJM Scholarship]],"Not Applicable") -> Not Applicable
A13: 2486337 | B13: Spain | C13: Yes | D13: Yes | E13: Yes | F13: 92.43 | G13: Waiting List | H13: 12 | I13: =IF(AND(Table1[[#This Row],[Selected IM]]="Yes",Table1[[#This Row],[Selected MM]]="Yes",Table1[[#This Row],[Selected RM]]="Yes"),"Triple Yes",IF(OR((AND(Table1[[#This Row],[Selected IM]]="Yes",Table1[[#This Row],[Selected MM]]="No",Table1[[#This Row],[Selected RM]]="Yes")),(AND(Table1[[#This Row],[Selected IM]]="No",Table1[[#This Row],[Selected MM]]="Yes",Table1[[#This Row],[Selected RM]]="Yes"))),"Double Yes", IF(AND(Table1[[#This Row],[Selected IM]]="No",Table1[[#This Row],[Selected MM]]="No",Table1[[#This Row],[Selected RM]]="Yes"), "Single Yes", "Triple No"))) -> Triple Yes | J13: =IF(Table1[[#This Row],[Nationality]]="Nigeria",Table1[[#This Row],[EMJM Scholarship]],"Not Applicable") -> Not Applicable
... A320: 2511830 | B320: Madagascar | C320: No | D320: No | E320: Yes | F320: 50 | G320: N/A | H320: 319 | I320: =IF(AND(Table1[[#This Row],[Selected IM]]="Yes",Table1[[#This Row],[Selected MM]]="Yes",Table1[[#This Row],[Selected RM]]="Yes"),"Triple Yes",IF(OR((AND(Table1[[#This Row],[Selected IM]]="Yes",Table1[[#This Row],[Selected MM]]="No",Table1[[#This Row],[Selected RM]]="Yes")),(AND(Table1[[#This Row],[Selected IM]]="No",Table1[[#This Row],[Selected MM]]="Yes",Table1[[#This Row],[Selected RM]]="Yes"))),"Double Yes", IF(AND(Table1[[#This Row],[Selected IM]]="No",Table1[[#This Row],[Selected MM]]="No",Table1[[#This Row],[Selected RM]]="Yes"), "Single Yes", "Triple No"))) -> Single Yes | J320: =IF(Table1[[#This Row],[Nationality]]="Nigeria",Table1[[#This Row],[EMJM Scholarship]],"Not Applicable") -> Not Applicable
A321: 2410224 | C321: No | D321: No | E321: No | I321: =IF(AND(Table1[[#This Row],[Selected IM]]="Yes",Table1[[#This Row],[Selected MM]]="Yes",Table1[[#This Row],[Selected RM]]="Yes"),"Triple Yes",IF(OR((AND(Table1[[#This Row],[Selected IM]]="Yes",Table1[[#This Row],[Selected MM]]="No",Table1[[#This Row],[Selected RM]]="Yes")),(AND(Table1[[#This Row],[Selected IM]]="No",Table1[[#This Row],[Selected MM]]="Yes",Table1[[#This Row],[Selected RM]]="Yes"))),"Double Yes", IF(AND(Table1[[#This Row],[Selected IM]]="No",Table1[[#This Row],[Selected MM]]="No",Table1[[#This Row],[Selected RM]]="Yes"), "Single Yes", "Triple No"))) -> Triple No | J321: =IF(Table1[[#This Row],[Nationality]]="Nigeria",Table1[[#This Row],[EMJM Scholarship]],"Not Applicable") -> Not Applicable
A322: 2414547 | C322: No | D322: No | E322: No | I322: =IF(AND(Table1[[#This Row],[Selected IM]]="Yes",Table1[[#This Row],[Selected MM]]="Yes",Table1[[#This Row],[Selected RM]]="Yes"),"Triple Yes",IF(OR((AND(Table1[[#This Row],[Selected IM]]="Yes",Table1[[#This Row],[Selected MM]]="No",Table1[[#This Row],[Selected RM]]="Yes")),(AND(Table1[[#This Row],[Selected IM]]="No",Table1[[#This Row],[Selected MM]]="Yes",Table1[[#This Row],[Selected RM]]="Yes"))),"Double Yes", IF(AND(Table1[[#This Row],[Selected IM]]="No",Table1[[#This Row],[Selected MM]]="No",Table1[[#This Row],[Selected RM]]="Yes"), "Single Yes", "Triple No"))) -> Triple No | J322: =IF(Table1[[#This Row],[Nationality]]="Nigeria",Table1[[#This Row],[EMJM Scholarship]],"Not Applicable") -> Not Applicable
A323: 2414551 | C323: No | D323: No | E323: No | I323: =IF(AND(Table1[[#This Row],[Selected IM]]="Yes",Table1[[#This Row],[Selected MM]]="Yes",Table1[[#This Row],[Selected RM]]="Yes"),"Triple Yes",IF(OR((AND(Table1[[#This Row],[Selected IM]]="Yes",Table1[[#This Row],[Selected MM]]="No",Table1[[#This Row],[Selected RM]]="Yes")),(AND(Table1[[#This Row],[Selected IM]]="No",Table1[[#This Row],[Selected MM]]="Yes",Table1[[#This Row],[Selected RM]]="Yes"))),"Double Yes", IF(AND(Table1[[#This Row],[Selected IM]]="No",Table1[[#This Row],[Selected MM]]="No",Table1[[#This Row],[Selected RM]]="Yes"), "Single Yes", "Triple No"))) -> Triple No | J323: =IF(Table1[[#This Row],[Nationality]]="Nigeria",Table1[[#This Row],[EMJM Scholarship]],"Not Applicable") -> Not Applicable
A324: 2414561 | C324: No | D324: No | E324: No | I324: =IF(AND(Table1[[#This Row],[Selected IM]]="Yes",Table1[[#This Row],[Selected MM]]="Yes",Table1[[#This Row],[Selected RM]]="Yes"),"Triple Yes",IF(OR((AND(Table1[[#This Row],[Selected IM]]="Yes",Table1[[#This Row],[Selected MM]]="No",Table1[[#This Row],[Selected RM]]="Yes")),(AND(Table1[[#This Row],[Selected IM]]="No",Table1[[#This Row],[Selected MM]]="Yes",Table1[[#This Row],[Selected RM]]="Yes"))),"Double Yes", IF(AND(Table1[[#This Row],[Selected IM]]="No",Table1[[#This Row],[Selected MM]]="No",Table1[[#This Row],[Selected RM]]="Yes"), "Single Yes", "Triple No"))) -> Triple No | J324: =IF(Table1[[#This Row],[Nationality]]="Nigeria",Table1[[#This Row],[EMJM Scholarship]],"Not Applicable") -> Not Applicable
A325: 2414564 | C325: No | D325: No | E325: No | I325: =IF(AND(Table1[[#This Row],[Selected IM]]="Yes",Table1[[#This Row],[Selected MM]]="Yes",Table1[[#This Row],[Selected RM]]="Yes"),"Triple Yes",IF(OR((AND(Table1[[#This Row],[Selected IM]]="Yes",Table1[[#This Row],[Selected MM]]="No",Table1[[#This Row],[Selected RM]]="Yes")),(AND(Table1[[#This Row],[Selected IM]]="No",Table1[[#This Row],[Selected MM]]="Yes",Table1[[#This Row],[Selected RM]]="Yes"))),"Double Yes", IF(AND(Table1[[#This Row],[Selected IM]]="No",Table1[[#This Row],[Selected MM]]="No",Table1[[#This Row],[Selected RM]]="Yes"), "Single Yes", "Triple No"))) -> Triple No | J325: =IF(Table1[[#This Row],[Nationality]]="Nigeria",Table1[[#This Row],[EMJM Scholarship]],"Not Applicable") -> Not Applicable
A326: 2414568 | C326: No | D326: No | E326: No | I326: =IF(AND(Table1[[#This Row],[Selected IM]]="Yes",Table1[[#This Row],[Selected MM]]="Yes",Table1[[#This Row],[Selected RM]]="Yes"),"Triple Yes",IF(OR((AND(Table1[[#This Row],[Selected IM]]="Yes",Table1[[#This Row],[Selected MM]]="No",Table1[[#This Row],[Selected RM]]="Yes")),(AND(Table1[[#This Row],[Selected IM]]="No",Table1[[#This Row],[Selected MM]]="Yes",Table1[[#This Row],[Selected RM]]="Yes"))),"Double Yes", IF(AND(Table1[[#This Row],[Selected IM]]="No",Table1[[#This Row],[Selected MM]]="No",Table1[[#This Row],[Selected RM]]="Yes"), "Single Yes", "Triple No"))) -> Triple No | J326: =IF(Table1[[#This Row],[Nationality]]="Nigeria",Table1[[#This Row],[EMJM Scholarship]],"Not Applicable") -> Not Applicable
A327: 2414574 | C327: No | D327: No | E327: No | I327: =IF(AND(Table1[[#This Row],[Selected IM]]="Yes",Table1[[#This Row],[Selected MM]]="Yes",Table1[[#This Row],[Selected RM]]="Yes"),"Triple Yes",IF(OR((AND(Table1[[#This Row],[Selected IM]]="Yes",Table1[[#This Row],[Selected MM]]="No",Table1[[#This Row],[Selected RM]]="Yes")),(AND(Table1[[#This Row],[Selected IM]]="No",Table1[[#This Row],[Selected MM]]="Yes",Table1[[#This Row],[Selected RM]]="Yes"))),"Double Yes", IF(AND(Table1[[#This Row],[Selected IM]]="No",Table1[[#This Row],[Selected MM]]="No",Table1[[#This Row],[Selected RM]]="Yes"), "Single Yes", "Triple No"))) -> Triple No | J327: =IF(Table1[[#This Row],[Nationality]]="Nigeria",Table1[[#This Row],[EMJM Scholarship]],"Not Applicable") -> Not Applicable
A328: 2414588 | C328: No | D328: No | E328: No | I328: =IF(AND(Table1[[#This Row],[Selected IM]]="Yes",Table1[[#This Row],[Selected MM]]="Yes",Table1[[#This Row],[Selected RM]]="Yes"),"Triple Yes",IF(OR((AND(Table1[[#This Row],[Selected IM]]="Yes",Table1[[#This Row],[Selected MM]]="No",Table1[[#This Row],[Selected RM]]="Yes")),(AND(Table1[[#This Row],[Selected IM]]="No",Table1[[#This Row],[Selected MM]]="Yes",Table1[[#This Row],[Selected RM]]="Yes"))),"Double Yes", IF(AND(Table1[[#This Row],[Selected IM]]="No",Table1[[#This Row],[Selected MM]]="No",Table1[[#This Row],[Selected RM]]="Yes"), "Single Yes", "Triple No"))) -> Triple No | J328: =IF(Table1[[#This Row],[Nationality]]="Nigeria",Table1[[#This Row],[EMJM Scholarship]],"Not Applicable") -> Not Applicable
A329: 2414591 | C329: No | D329: No | E329: No | I329: =IF(AND(Table1[[#This Row],[Selected IM]]="Yes",Table1[[#This Row],[Selected MM]]="Yes",Table1[[#This Row],[Selected RM]]="Yes"),"Triple Yes",IF(OR((AND(Table1[[#This Row],[Selected IM]]="Yes",Table1[[#This Row],[Selected MM]]="No",Table1[[#This Row],[Selected RM]]="Yes")),(AND(Table1[[#This Row],[Selected IM]]="No",Table1[[#This Row],[Selected MM]]="Yes",Table1[[#This Row],[Selected RM]]="Yes"))),"Double Yes", IF(AND(Table1[[#This Row],[Selected IM]]="No",Table1[[#This Row],[Selected MM]]="No",Table1[[#This Row],[Selected RM]]="Yes"), "Single Yes", "Triple No"))) -> Triple No | J329: =IF(Table1[[#This Row],[Nationality]]="Nigeria",Table1[[#This Row],[EMJM Scholarship]],"Not Applicable") -> Not Applicable
A330: 2414605 | C330: No | D330: No | E330: No | I330: =IF(AND(Table1[[#This Row],[Selected IM]]="Yes",Table1[[#This Row],[Selected MM]]="Yes",Table1[[#This Row],[Selected RM]]="Yes"),"Triple Yes",IF(OR((AND(Table1[[#This Row],[Selected IM]]="Yes",Table1[[#This Row],[Selected MM]]="No",Table1[[#This Row],[Selected RM]]="Yes")),(AND(Table1[[#This Row],[Selected IM]]="No",Table1[[#This Row],[Selected MM]]="Yes",Table1[[#This Row],[Selected RM]]="Yes"))),"Double Yes", IF(AND(Table1[[#This Row],[Selected IM]]="No",Table1[[#This Row],[Selected MM]]="No",Table1[[#This Row],[Selected RM]]="Yes"), "Single Yes", "Triple No"))) -> Triple No | J330: =IF(Table1[[#This Row],[Nationality]]="Nigeria",Table1[[#This Row],[EMJM Scholarship]],"Not Applicable") -> Not Applicable
A331: 2414670 | C331: No | D331: No | E331: No | I331: =IF(AND(Table1[[#This Row],[Selected IM]]="Yes",Table1[[#This Row],[Selected MM]]="Yes",Table1[[#This Row],[Selected RM]]="Yes"),"Triple Yes",IF(OR((AND(Table1[[#This Row],[Selected IM]]="Yes",Table1[[#This Row],[Selected MM]]="No",Table1[[#This Row],[Selected RM]]="Yes")),(AND(Table1[[#This Row],[Selected IM]]="No",Table1[[#This Row],[Selected MM]]="Yes",Table1[[#This Row],[Selected RM]]="Yes"))),"Double Yes", IF(AND(Table1[[#This Row],[Selected IM]]="No",Table1[[#This Row],[Selected MM]]="No",Table1[[#This Row],[Selected RM]]="Yes"), "Single Yes", "Triple No"))) -> Triple No | J331: =IF(Table1[[#This Row],[Nationality]]="Nigeria",Table1[[#This Row],[EMJM Scholarship]],"Not Applicable") -> Not Applicable
A332: 2414709 | C332: No | D332: No | E332: No | I332: =IF(AND(Table1[[#This Row],[Selected IM]]="Yes",Table1[[#This Row],[Selected MM]]="Yes",Table1[[#This Row],[Selected RM]]="Yes"),"Triple Yes",IF(OR((AND(Table1[[#This Row],[Selected IM]]="Yes",Table1[[#This Row],[Selected MM]]="No",Table1[[#This Row],[Selected RM]]="Yes")),(AND(Table1[[#This Row],[Selected IM]]="No",Table1[[#This Row],[Selected MM]]="Yes",Table1[[#This Row],[Selected RM]]="Yes"))),"Double Yes", IF(AND(Table1[[#This Row],[Selected IM]]="No",Table1[[#This Row],[Selected MM]]="No",Table1[[#This Row],[Selected RM]]="Yes"), "Single Yes", "Triple No"))) -> Triple No | J332: =IF(Table1[[#This Row],[Nationality]]="Nigeria",Table1[[#This Row],[EMJM Scholarship]],"Not Applicable") -> Not Applicable
... A2466: 2523830 | C2466: No | D2466: No | E2466: No | I2466: =IF(AND(Table1[[#This Row],[Selected IM]]="Yes",Table1[[#This Row],[Selected MM]]="Yes",Table1[[#This Row],[Selected RM]]="Yes"),"Triple Yes",IF(OR((AND(Table1[[#This Row],[Selected IM]]="Yes",Table1[[#This Row],[Selected MM]]="No",Table1[[#This Row],[Selected RM]]="Yes")),(AND(Table1[[#This Row],[Selected IM]]="No",Table1[[#This Row],[Selected MM]]="Yes",Table1[[#This Row],[Selected RM]]="Yes"))),"Double Yes", IF(AND(Table1[[#This Row],[Selected IM]]="No",Table1[[#This Row],[Selected MM]]="No",Table1[[#This Row],[Selected RM]]="Yes"), "Single Yes", "Triple No"))) -> Triple No | J2466: =IF(Table1[[#This Row],[Nationality]]="Nigeria",Table1[[#This Row],[EMJM Scholarship]],"Not Applicable") -> Not Applicable

Sheet DASHBOARD

Sheet Sheet1
G7: AWAITING | H7: N/A, | I7: N/A.
G8: 2513497 | H8: 2523681 | I8: 2486714
G9: 2501634 | H9: 2416993 | I9: 2461416
G10: 2489553 | H10: 2480650 | I10: 2429237
G11: 2438563 | H11: 2468821 | I11: 2463467
G12: 2486137 | H12: 2507896 | I12: 2482203
G13: 2414601 | H13: 2459982 | I13: 2421789
G14: 2414563 | H14: 2417391 | I14: 2461653
G15: 2495429 | H15: 2434117 | I15: 2488646
G16: 2489632 | H16: 2424251
G17: 2414590 | H17: 2464142
G18: 2444879 | H18: 2414548
